{
 "cells": [
  {
   "cell_type": "code",
   "execution_count": 1,
   "id": "d26793ca-90d6-4f1f-8847-d541ebcfd9d8",
   "metadata": {},
   "outputs": [
    {
     "name": "stdout",
     "output_type": "stream",
     "text": [
      "Requirement already satisfied: keras in c:\\users\\dell\\anaconda3\\lib\\site-packages (3.6.0)\n",
      "Requirement already satisfied: absl-py in c:\\users\\dell\\anaconda3\\lib\\site-packages (from keras) (2.1.0)\n",
      "Requirement already satisfied: numpy in c:\\users\\dell\\anaconda3\\lib\\site-packages (from keras) (1.26.4)\n",
      "Requirement already satisfied: rich in c:\\users\\dell\\anaconda3\\lib\\site-packages (from keras) (13.3.5)\n",
      "Requirement already satisfied: namex in c:\\users\\dell\\anaconda3\\lib\\site-packages (from keras) (0.0.8)\n",
      "Requirement already satisfied: h5py in c:\\users\\dell\\anaconda3\\lib\\site-packages (from keras) (3.11.0)\n",
      "Requirement already satisfied: optree in c:\\users\\dell\\anaconda3\\lib\\site-packages (from keras) (0.13.0)\n",
      "Requirement already satisfied: ml-dtypes in c:\\users\\dell\\anaconda3\\lib\\site-packages (from keras) (0.4.1)\n",
      "Requirement already satisfied: packaging in c:\\users\\dell\\anaconda3\\lib\\site-packages (from keras) (23.2)\n",
      "Requirement already satisfied: typing-extensions>=4.5.0 in c:\\users\\dell\\anaconda3\\lib\\site-packages (from optree->keras) (4.11.0)\n",
      "Requirement already satisfied: markdown-it-py<3.0.0,>=2.2.0 in c:\\users\\dell\\anaconda3\\lib\\site-packages (from rich->keras) (2.2.0)\n",
      "Requirement already satisfied: pygments<3.0.0,>=2.13.0 in c:\\users\\dell\\anaconda3\\lib\\site-packages (from rich->keras) (2.15.1)\n",
      "Requirement already satisfied: mdurl~=0.1 in c:\\users\\dell\\anaconda3\\lib\\site-packages (from markdown-it-py<3.0.0,>=2.2.0->rich->keras) (0.1.0)\n",
      "Note: you may need to restart the kernel to use updated packages.\n"
     ]
    }
   ],
   "source": [
    "pip install keras\n"
   ]
  },
  {
   "cell_type": "code",
   "execution_count": 2,
   "id": "879acd86-af4c-44ab-8549-148ecc6e4872",
   "metadata": {},
   "outputs": [
    {
     "name": "stdout",
     "output_type": "stream",
     "text": [
      "Requirement already satisfied: tensorflow in c:\\users\\dell\\anaconda3\\lib\\site-packages (2.17.0)\n",
      "Requirement already satisfied: tensorflow-intel==2.17.0 in c:\\users\\dell\\anaconda3\\lib\\site-packages (from tensorflow) (2.17.0)\n",
      "Requirement already satisfied: absl-py>=1.0.0 in c:\\users\\dell\\anaconda3\\lib\\site-packages (from tensorflow-intel==2.17.0->tensorflow) (2.1.0)\n",
      "Requirement already satisfied: astunparse>=1.6.0 in c:\\users\\dell\\anaconda3\\lib\\site-packages (from tensorflow-intel==2.17.0->tensorflow) (1.6.3)\n",
      "Requirement already satisfied: flatbuffers>=24.3.25 in c:\\users\\dell\\anaconda3\\lib\\site-packages (from tensorflow-intel==2.17.0->tensorflow) (24.3.25)\n",
      "Requirement already satisfied: gast!=0.5.0,!=0.5.1,!=0.5.2,>=0.2.1 in c:\\users\\dell\\anaconda3\\lib\\site-packages (from tensorflow-intel==2.17.0->tensorflow) (0.6.0)\n",
      "Requirement already satisfied: google-pasta>=0.1.1 in c:\\users\\dell\\anaconda3\\lib\\site-packages (from tensorflow-intel==2.17.0->tensorflow) (0.2.0)\n",
      "Requirement already satisfied: h5py>=3.10.0 in c:\\users\\dell\\anaconda3\\lib\\site-packages (from tensorflow-intel==2.17.0->tensorflow) (3.11.0)\n",
      "Requirement already satisfied: libclang>=13.0.0 in c:\\users\\dell\\anaconda3\\lib\\site-packages (from tensorflow-intel==2.17.0->tensorflow) (18.1.1)\n",
      "Requirement already satisfied: ml-dtypes<0.5.0,>=0.3.1 in c:\\users\\dell\\anaconda3\\lib\\site-packages (from tensorflow-intel==2.17.0->tensorflow) (0.4.1)\n",
      "Requirement already satisfied: opt-einsum>=2.3.2 in c:\\users\\dell\\anaconda3\\lib\\site-packages (from tensorflow-intel==2.17.0->tensorflow) (3.4.0)\n",
      "Requirement already satisfied: packaging in c:\\users\\dell\\anaconda3\\lib\\site-packages (from tensorflow-intel==2.17.0->tensorflow) (23.2)\n",
      "Requirement already satisfied: protobuf!=4.21.0,!=4.21.1,!=4.21.2,!=4.21.3,!=4.21.4,!=4.21.5,<5.0.0dev,>=3.20.3 in c:\\users\\dell\\anaconda3\\lib\\site-packages (from tensorflow-intel==2.17.0->tensorflow) (3.20.3)\n",
      "Requirement already satisfied: requests<3,>=2.21.0 in c:\\users\\dell\\anaconda3\\lib\\site-packages (from tensorflow-intel==2.17.0->tensorflow) (2.32.2)\n",
      "Requirement already satisfied: setuptools in c:\\users\\dell\\anaconda3\\lib\\site-packages (from tensorflow-intel==2.17.0->tensorflow) (69.5.1)\n",
      "Requirement already satisfied: six>=1.12.0 in c:\\users\\dell\\anaconda3\\lib\\site-packages (from tensorflow-intel==2.17.0->tensorflow) (1.16.0)\n",
      "Requirement already satisfied: termcolor>=1.1.0 in c:\\users\\dell\\anaconda3\\lib\\site-packages (from tensorflow-intel==2.17.0->tensorflow) (2.5.0)\n",
      "Requirement already satisfied: typing-extensions>=3.6.6 in c:\\users\\dell\\anaconda3\\lib\\site-packages (from tensorflow-intel==2.17.0->tensorflow) (4.11.0)\n",
      "Requirement already satisfied: wrapt>=1.11.0 in c:\\users\\dell\\anaconda3\\lib\\site-packages (from tensorflow-intel==2.17.0->tensorflow) (1.14.1)\n",
      "Requirement already satisfied: grpcio<2.0,>=1.24.3 in c:\\users\\dell\\anaconda3\\lib\\site-packages (from tensorflow-intel==2.17.0->tensorflow) (1.67.0)\n",
      "Requirement already satisfied: tensorboard<2.18,>=2.17 in c:\\users\\dell\\anaconda3\\lib\\site-packages (from tensorflow-intel==2.17.0->tensorflow) (2.17.1)\n",
      "Requirement already satisfied: keras>=3.2.0 in c:\\users\\dell\\anaconda3\\lib\\site-packages (from tensorflow-intel==2.17.0->tensorflow) (3.6.0)\n",
      "Requirement already satisfied: numpy<2.0.0,>=1.26.0 in c:\\users\\dell\\anaconda3\\lib\\site-packages (from tensorflow-intel==2.17.0->tensorflow) (1.26.4)\n",
      "Requirement already satisfied: wheel<1.0,>=0.23.0 in c:\\users\\dell\\anaconda3\\lib\\site-packages (from astunparse>=1.6.0->tensorflow-intel==2.17.0->tensorflow) (0.43.0)\n",
      "Requirement already satisfied: rich in c:\\users\\dell\\anaconda3\\lib\\site-packages (from keras>=3.2.0->tensorflow-intel==2.17.0->tensorflow) (13.3.5)\n",
      "Requirement already satisfied: namex in c:\\users\\dell\\anaconda3\\lib\\site-packages (from keras>=3.2.0->tensorflow-intel==2.17.0->tensorflow) (0.0.8)\n",
      "Requirement already satisfied: optree in c:\\users\\dell\\anaconda3\\lib\\site-packages (from keras>=3.2.0->tensorflow-intel==2.17.0->tensorflow) (0.13.0)\n",
      "Requirement already satisfied: charset-normalizer<4,>=2 in c:\\users\\dell\\anaconda3\\lib\\site-packages (from requests<3,>=2.21.0->tensorflow-intel==2.17.0->tensorflow) (2.0.4)\n",
      "Requirement already satisfied: idna<4,>=2.5 in c:\\users\\dell\\anaconda3\\lib\\site-packages (from requests<3,>=2.21.0->tensorflow-intel==2.17.0->tensorflow) (3.7)\n",
      "Requirement already satisfied: urllib3<3,>=1.21.1 in c:\\users\\dell\\anaconda3\\lib\\site-packages (from requests<3,>=2.21.0->tensorflow-intel==2.17.0->tensorflow) (2.2.2)\n",
      "Requirement already satisfied: certifi>=2017.4.17 in c:\\users\\dell\\anaconda3\\lib\\site-packages (from requests<3,>=2.21.0->tensorflow-intel==2.17.0->tensorflow) (2024.8.30)\n",
      "Requirement already satisfied: markdown>=2.6.8 in c:\\users\\dell\\anaconda3\\lib\\site-packages (from tensorboard<2.18,>=2.17->tensorflow-intel==2.17.0->tensorflow) (3.4.1)\n",
      "Requirement already satisfied: tensorboard-data-server<0.8.0,>=0.7.0 in c:\\users\\dell\\anaconda3\\lib\\site-packages (from tensorboard<2.18,>=2.17->tensorflow-intel==2.17.0->tensorflow) (0.7.2)\n",
      "Requirement already satisfied: werkzeug>=1.0.1 in c:\\users\\dell\\anaconda3\\lib\\site-packages (from tensorboard<2.18,>=2.17->tensorflow-intel==2.17.0->tensorflow) (3.0.3)\n",
      "Requirement already satisfied: MarkupSafe>=2.1.1 in c:\\users\\dell\\anaconda3\\lib\\site-packages (from werkzeug>=1.0.1->tensorboard<2.18,>=2.17->tensorflow-intel==2.17.0->tensorflow) (2.1.3)\n",
      "Requirement already satisfied: markdown-it-py<3.0.0,>=2.2.0 in c:\\users\\dell\\anaconda3\\lib\\site-packages (from rich->keras>=3.2.0->tensorflow-intel==2.17.0->tensorflow) (2.2.0)\n",
      "Requirement already satisfied: pygments<3.0.0,>=2.13.0 in c:\\users\\dell\\anaconda3\\lib\\site-packages (from rich->keras>=3.2.0->tensorflow-intel==2.17.0->tensorflow) (2.15.1)\n",
      "Requirement already satisfied: mdurl~=0.1 in c:\\users\\dell\\anaconda3\\lib\\site-packages (from markdown-it-py<3.0.0,>=2.2.0->rich->keras>=3.2.0->tensorflow-intel==2.17.0->tensorflow) (0.1.0)\n",
      "Note: you may need to restart the kernel to use updated packages.\n"
     ]
    }
   ],
   "source": [
    "pip install tensorflow\n"
   ]
  },
  {
   "cell_type": "code",
   "execution_count": 3,
   "id": "d9b23ca5-11b7-4852-9542-84884d758155",
   "metadata": {},
   "outputs": [],
   "source": [
    "from tensorflow.keras.preprocessing.image import ImageDataGenerator\n"
   ]
  },
  {
   "cell_type": "code",
   "execution_count": 4,
   "id": "316b64bb-0e6e-49cf-becb-eb51208e7608",
   "metadata": {},
   "outputs": [],
   "source": [
    "train_dir = 'train'\n",
    "test_dir = 'test'"
   ]
  },
  {
   "cell_type": "code",
   "execution_count": 5,
   "id": "5ab22489-19fd-45ae-8a01-2cd8417ce86f",
   "metadata": {},
   "outputs": [],
   "source": [
    "input_shape = (128, 128, 3) "
   ]
  },
  {
   "cell_type": "code",
   "execution_count": 6,
   "id": "5d7be4fd-2331-4398-8661-d78b56b27044",
   "metadata": {},
   "outputs": [],
   "source": [
    "batch_size = 32\n",
    "epochs = 10"
   ]
  },
  {
   "cell_type": "code",
   "execution_count": 13,
   "id": "18e2a504-e067-4292-9517-43290bcab45d",
   "metadata": {},
   "outputs": [],
   "source": [
    "# Create separate instances of ImageDataGenerator for train and test train\n",
    "train_data_generator = ImageDataGenerator(rescale=1./255)  # For training train\n",
    "test_data_generator = ImageDataGenerator(rescale=1./255)  # For testing train\n"
   ]
  },
  {
   "cell_type": "code",
   "execution_count": 15,
   "id": "a9e53701-e6d3-4ea9-a44e-1df9f26f12a2",
   "metadata": {},
   "outputs": [
    {
     "name": "stdout",
     "output_type": "stream",
     "text": [
      "Found 4010 images belonging to 2 classes.\n"
     ]
    }
   ],
   "source": [
    "# Load and preprocess the training images using ImageDataGenerator\n",
    "train_generator = train_data_generator.flow_from_directory(\n",
    "    train_dir,\n",
    "    target_size=(input_shape[0], input_shape[1]),\n",
    "    batch_size=batch_size,\n",
    "    class_mode='categorical')"
   ]
  },
  {
   "cell_type": "code",
   "execution_count": 17,
   "id": "95795741-efa5-4148-8850-9c9cc3915ec5",
   "metadata": {},
   "outputs": [
    {
     "name": "stdout",
     "output_type": "stream",
     "text": [
      "Found 3543 images belonging to 2 classes.\n"
     ]
    }
   ],
   "source": [
    "# Load and preprocess the testing images using ImageDataGenerator\n",
    "test_generator = test_data_generator.flow_from_directory(\n",
    "    test_dir,\n",
    "    target_size=(input_shape[0], input_shape[1]),\n",
    "    batch_size=batch_size,\n",
    "    class_mode='categorical')\n"
   ]
  },
  {
   "cell_type": "code",
   "execution_count": 19,
   "id": "baae2efb-b227-4fca-b831-16866b49ef6f",
   "metadata": {},
   "outputs": [],
   "source": [
    "from keras.models import Sequential\n",
    "from keras.layers import Conv2D, MaxPooling2D\n",
    "from keras.layers import Activation, Dropout, Flatten, Dense"
   ]
  },
  {
   "cell_type": "code",
   "execution_count": 21,
   "id": "ae26f796-d0a3-4f87-ba9d-1ddd430c0b05",
   "metadata": {},
   "outputs": [
    {
     "name": "stderr",
     "output_type": "stream",
     "text": [
      "C:\\Users\\DELL\\anaconda3\\Lib\\site-packages\\keras\\src\\layers\\convolutional\\base_conv.py:107: UserWarning: Do not pass an `input_shape`/`input_dim` argument to a layer. When using Sequential models, prefer using an `Input(shape)` object as the first layer in the model instead.\n",
      "  super().__init__(activity_regularizer=activity_regularizer, **kwargs)\n"
     ]
    }
   ],
   "source": [
    "# Define the model architecture\n",
    "model = Sequential()\n",
    "model.add(Conv2D(32, (3, 3), input_shape=input_shape))\n",
    "model.add(Activation('relu'))\n",
    "model.add(MaxPooling2D(pool_size=(2, 2)))\n",
    "\n",
    "model.add(Conv2D(64, (3, 3)))\n",
    "model.add(Activation('relu'))\n",
    "model.add(MaxPooling2D(pool_size=(2, 2)))\n",
    "\n",
    "model.add(Flatten())\n",
    "model.add(Dense(64))\n",
    "model.add(Activation('relu'))\n",
    "model.add(Dropout(0.5))\n",
    "model.add(Dense(2))\n",
    "model.add(Activation('softmax'))\n",
    "\n",
    "# Compile the model\n",
    "model.compile(loss='categorical_crossentropy', optimizer='adam', metrics=['accuracy'])\n"
   ]
  },
  {
   "cell_type": "code",
   "execution_count": 23,
   "id": "b0239dcd-a91d-4c40-b29c-606abf717d4b",
   "metadata": {},
   "outputs": [
    {
     "name": "stderr",
     "output_type": "stream",
     "text": [
      "C:\\Users\\DELL\\anaconda3\\Lib\\site-packages\\keras\\src\\trainers\\data_adapters\\py_dataset_adapter.py:121: UserWarning: Your `PyDataset` class should call `super().__init__(**kwargs)` in its constructor. `**kwargs` can include `workers`, `use_multiprocessing`, `max_queue_size`. Do not pass these arguments to `fit()`, as they will be ignored.\n",
      "  self._warn_if_super_not_called()\n"
     ]
    },
    {
     "name": "stdout",
     "output_type": "stream",
     "text": [
      "Epoch 1/10\n",
      "\u001b[1m125/125\u001b[0m \u001b[32m━━━━━━━━━━━━━━━━━━━━\u001b[0m\u001b[37m\u001b[0m \u001b[1m75s\u001b[0m 578ms/step - accuracy: 0.7312 - loss: 0.6810\n",
      "Epoch 2/10\n",
      "\u001b[1m125/125\u001b[0m \u001b[32m━━━━━━━━━━━━━━━━━━━━\u001b[0m\u001b[37m\u001b[0m \u001b[1m0s\u001b[0m 184us/step - accuracy: 0.9062 - loss: 0.3031 \n",
      "Epoch 3/10\n"
     ]
    },
    {
     "name": "stderr",
     "output_type": "stream",
     "text": [
      "C:\\Users\\DELL\\anaconda3\\Lib\\contextlib.py:158: UserWarning: Your input ran out of data; interrupting training. Make sure that your dataset or generator can generate at least `steps_per_epoch * epochs` batches. You may need to use the `.repeat()` function when building your dataset.\n",
      "  self.gen.throw(value)\n"
     ]
    },
    {
     "name": "stdout",
     "output_type": "stream",
     "text": [
      "\u001b[1m125/125\u001b[0m \u001b[32m━━━━━━━━━━━━━━━━━━━━\u001b[0m\u001b[37m\u001b[0m \u001b[1m46s\u001b[0m 366ms/step - accuracy: 0.9354 - loss: 0.1922\n",
      "Epoch 4/10\n",
      "\u001b[1m125/125\u001b[0m \u001b[32m━━━━━━━━━━━━━━━━━━━━\u001b[0m\u001b[37m\u001b[0m \u001b[1m0s\u001b[0m 126us/step - accuracy: 0.9375 - loss: 0.2099 \n",
      "Epoch 5/10\n",
      "\u001b[1m125/125\u001b[0m \u001b[32m━━━━━━━━━━━━━━━━━━━━\u001b[0m\u001b[37m\u001b[0m \u001b[1m43s\u001b[0m 346ms/step - accuracy: 0.9509 - loss: 0.1464\n",
      "Epoch 6/10\n",
      "\u001b[1m125/125\u001b[0m \u001b[32m━━━━━━━━━━━━━━━━━━━━\u001b[0m\u001b[37m\u001b[0m \u001b[1m0s\u001b[0m 126us/step - accuracy: 0.9062 - loss: 0.2031 \n",
      "Epoch 7/10\n",
      "\u001b[1m125/125\u001b[0m \u001b[32m━━━━━━━━━━━━━━━━━━━━\u001b[0m\u001b[37m\u001b[0m \u001b[1m44s\u001b[0m 349ms/step - accuracy: 0.9555 - loss: 0.1181\n",
      "Epoch 8/10\n",
      "\u001b[1m125/125\u001b[0m \u001b[32m━━━━━━━━━━━━━━━━━━━━\u001b[0m\u001b[37m\u001b[0m \u001b[1m0s\u001b[0m 60us/step - accuracy: 1.0000 - loss: 0.0662  \n",
      "Epoch 9/10\n",
      "\u001b[1m125/125\u001b[0m \u001b[32m━━━━━━━━━━━━━━━━━━━━\u001b[0m\u001b[37m\u001b[0m \u001b[1m45s\u001b[0m 363ms/step - accuracy: 0.9662 - loss: 0.0887\n",
      "Epoch 10/10\n",
      "\u001b[1m125/125\u001b[0m \u001b[32m━━━━━━━━━━━━━━━━━━━━\u001b[0m\u001b[37m\u001b[0m \u001b[1m0s\u001b[0m 126us/step - accuracy: 1.0000 - loss: 0.0581 \n"
     ]
    },
    {
     "data": {
      "text/plain": [
       "<keras.src.callbacks.history.History at 0x1bebd3376b0>"
      ]
     },
     "execution_count": 23,
     "metadata": {},
     "output_type": "execute_result"
    }
   ],
   "source": [
    "# Train the model\n",
    "model.fit(train_generator, steps_per_epoch=train_generator.n // batch_size, epochs=epochs)\n"
   ]
  },
  {
   "cell_type": "code",
   "execution_count": 27,
   "id": "cc74fc79-a91d-49d8-8cca-3af5e31d1615",
   "metadata": {},
   "outputs": [
    {
     "name": "stdout",
     "output_type": "stream",
     "text": [
      "\u001b[1m 29/111\u001b[0m \u001b[32m━━━━━\u001b[0m\u001b[37m━━━━━━━━━━━━━━━\u001b[0m \u001b[1m15s\u001b[0m 186ms/step - accuracy: 0.7746 - loss: 0.7281"
     ]
    },
    {
     "ename": "UnknownError",
     "evalue": "Graph execution error:\n\nDetected at node PyFunc defined at (most recent call last):\n<stack traces unavailable>\nFileNotFoundError: [Errno 2] No such file or directory: 'test\\\\with_mask\\\\with_mask_2001.jpg'\nTraceback (most recent call last):\n\n  File \"C:\\Users\\DELL\\anaconda3\\Lib\\site-packages\\tensorflow\\python\\ops\\script_ops.py\", line 270, in __call__\n    ret = func(*args)\n          ^^^^^^^^^^^\n\n  File \"C:\\Users\\DELL\\anaconda3\\Lib\\site-packages\\tensorflow\\python\\autograph\\impl\\api.py\", line 643, in wrapper\n    return func(*args, **kwargs)\n           ^^^^^^^^^^^^^^^^^^^^^\n\n  File \"C:\\Users\\DELL\\anaconda3\\Lib\\site-packages\\tensorflow\\python\\data\\ops\\from_generator_op.py\", line 198, in generator_py_func\n    values = next(generator_state.get_iterator(iterator_id))\n             ^^^^^^^^^^^^^^^^^^^^^^^^^^^^^^^^^^^^^^^^^^^^^^^\n\n  File \"C:\\Users\\DELL\\anaconda3\\Lib\\site-packages\\keras\\src\\trainers\\data_adapters\\py_dataset_adapter.py\", line 247, in _finite_generator\n    yield self.py_dataset[i]\n          ~~~~~~~~~~~~~~~^^^\n\n  File \"C:\\Users\\DELL\\anaconda3\\Lib\\site-packages\\keras\\src\\legacy\\preprocessing\\image.py\", line 68, in __getitem__\n    return self._get_batches_of_transformed_samples(index_array)\n           ^^^^^^^^^^^^^^^^^^^^^^^^^^^^^^^^^^^^^^^^^^^^^^^^^^^^^\n\n  File \"C:\\Users\\DELL\\anaconda3\\Lib\\site-packages\\keras\\src\\legacy\\preprocessing\\image.py\", line 313, in _get_batches_of_transformed_samples\n    img = image_utils.load_img(\n          ^^^^^^^^^^^^^^^^^^^^^\n\n  File \"C:\\Users\\DELL\\anaconda3\\Lib\\site-packages\\keras\\src\\utils\\image_utils.py\", line 235, in load_img\n    with open(path, \"rb\") as f:\n         ^^^^^^^^^^^^^^^^\n\nFileNotFoundError: [Errno 2] No such file or directory: 'test\\\\with_mask\\\\with_mask_2001.jpg'\n\n\n\t [[{{node PyFunc}}]]\n\t [[IteratorGetNext]] [Op:__inference_one_step_on_iterator_10972]",
     "output_type": "error",
     "traceback": [
      "\u001b[1;31m---------------------------------------------------------------------------\u001b[0m",
      "\u001b[1;31mUnknownError\u001b[0m                              Traceback (most recent call last)",
      "Cell \u001b[1;32mIn[27], line 2\u001b[0m\n\u001b[0;32m      1\u001b[0m \u001b[38;5;66;03m# Evaluate the model on the testing train\u001b[39;00m\n\u001b[1;32m----> 2\u001b[0m test_loss, test_accuracy \u001b[38;5;241m=\u001b[39m model\u001b[38;5;241m.\u001b[39mevaluate(test_generator)\n\u001b[0;32m      3\u001b[0m \u001b[38;5;28mprint\u001b[39m(\u001b[38;5;124m\"\u001b[39m\u001b[38;5;124mTest Loss:\u001b[39m\u001b[38;5;124m\"\u001b[39m, test_loss)\n\u001b[0;32m      4\u001b[0m \u001b[38;5;28mprint\u001b[39m(\u001b[38;5;124m\"\u001b[39m\u001b[38;5;124mTest Accuracy:\u001b[39m\u001b[38;5;124m\"\u001b[39m, test_accuracy)\n",
      "File \u001b[1;32m~\\anaconda3\\Lib\\site-packages\\keras\\src\\utils\\traceback_utils.py:122\u001b[0m, in \u001b[0;36mfilter_traceback.<locals>.error_handler\u001b[1;34m(*args, **kwargs)\u001b[0m\n\u001b[0;32m    119\u001b[0m     filtered_tb \u001b[38;5;241m=\u001b[39m _process_traceback_frames(e\u001b[38;5;241m.\u001b[39m__traceback__)\n\u001b[0;32m    120\u001b[0m     \u001b[38;5;66;03m# To get the full stack trace, call:\u001b[39;00m\n\u001b[0;32m    121\u001b[0m     \u001b[38;5;66;03m# `keras.config.disable_traceback_filtering()`\u001b[39;00m\n\u001b[1;32m--> 122\u001b[0m     \u001b[38;5;28;01mraise\u001b[39;00m e\u001b[38;5;241m.\u001b[39mwith_traceback(filtered_tb) \u001b[38;5;28;01mfrom\u001b[39;00m \u001b[38;5;28;01mNone\u001b[39;00m\n\u001b[0;32m    123\u001b[0m \u001b[38;5;28;01mfinally\u001b[39;00m:\n\u001b[0;32m    124\u001b[0m     \u001b[38;5;28;01mdel\u001b[39;00m filtered_tb\n",
      "File \u001b[1;32m~\\anaconda3\\Lib\\site-packages\\tensorflow\\python\\eager\\execute.py:53\u001b[0m, in \u001b[0;36mquick_execute\u001b[1;34m(op_name, num_outputs, inputs, attrs, ctx, name)\u001b[0m\n\u001b[0;32m     51\u001b[0m \u001b[38;5;28;01mtry\u001b[39;00m:\n\u001b[0;32m     52\u001b[0m   ctx\u001b[38;5;241m.\u001b[39mensure_initialized()\n\u001b[1;32m---> 53\u001b[0m   tensors \u001b[38;5;241m=\u001b[39m pywrap_tfe\u001b[38;5;241m.\u001b[39mTFE_Py_Execute(ctx\u001b[38;5;241m.\u001b[39m_handle, device_name, op_name,\n\u001b[0;32m     54\u001b[0m                                       inputs, attrs, num_outputs)\n\u001b[0;32m     55\u001b[0m \u001b[38;5;28;01mexcept\u001b[39;00m core\u001b[38;5;241m.\u001b[39m_NotOkStatusException \u001b[38;5;28;01mas\u001b[39;00m e:\n\u001b[0;32m     56\u001b[0m   \u001b[38;5;28;01mif\u001b[39;00m name \u001b[38;5;129;01mis\u001b[39;00m \u001b[38;5;129;01mnot\u001b[39;00m \u001b[38;5;28;01mNone\u001b[39;00m:\n",
      "\u001b[1;31mUnknownError\u001b[0m: Graph execution error:\n\nDetected at node PyFunc defined at (most recent call last):\n<stack traces unavailable>\nFileNotFoundError: [Errno 2] No such file or directory: 'test\\\\with_mask\\\\with_mask_2001.jpg'\nTraceback (most recent call last):\n\n  File \"C:\\Users\\DELL\\anaconda3\\Lib\\site-packages\\tensorflow\\python\\ops\\script_ops.py\", line 270, in __call__\n    ret = func(*args)\n          ^^^^^^^^^^^\n\n  File \"C:\\Users\\DELL\\anaconda3\\Lib\\site-packages\\tensorflow\\python\\autograph\\impl\\api.py\", line 643, in wrapper\n    return func(*args, **kwargs)\n           ^^^^^^^^^^^^^^^^^^^^^\n\n  File \"C:\\Users\\DELL\\anaconda3\\Lib\\site-packages\\tensorflow\\python\\data\\ops\\from_generator_op.py\", line 198, in generator_py_func\n    values = next(generator_state.get_iterator(iterator_id))\n             ^^^^^^^^^^^^^^^^^^^^^^^^^^^^^^^^^^^^^^^^^^^^^^^\n\n  File \"C:\\Users\\DELL\\anaconda3\\Lib\\site-packages\\keras\\src\\trainers\\data_adapters\\py_dataset_adapter.py\", line 247, in _finite_generator\n    yield self.py_dataset[i]\n          ~~~~~~~~~~~~~~~^^^\n\n  File \"C:\\Users\\DELL\\anaconda3\\Lib\\site-packages\\keras\\src\\legacy\\preprocessing\\image.py\", line 68, in __getitem__\n    return self._get_batches_of_transformed_samples(index_array)\n           ^^^^^^^^^^^^^^^^^^^^^^^^^^^^^^^^^^^^^^^^^^^^^^^^^^^^^\n\n  File \"C:\\Users\\DELL\\anaconda3\\Lib\\site-packages\\keras\\src\\legacy\\preprocessing\\image.py\", line 313, in _get_batches_of_transformed_samples\n    img = image_utils.load_img(\n          ^^^^^^^^^^^^^^^^^^^^^\n\n  File \"C:\\Users\\DELL\\anaconda3\\Lib\\site-packages\\keras\\src\\utils\\image_utils.py\", line 235, in load_img\n    with open(path, \"rb\") as f:\n         ^^^^^^^^^^^^^^^^\n\nFileNotFoundError: [Errno 2] No such file or directory: 'test\\\\with_mask\\\\with_mask_2001.jpg'\n\n\n\t [[{{node PyFunc}}]]\n\t [[IteratorGetNext]] [Op:__inference_one_step_on_iterator_10972]"
     ]
    }
   ],
   "source": [
    "# Evaluate the model on the testing train\n",
    "test_loss, test_accuracy = model.evaluate(test_generator)\n",
    "print(\"Test Loss:\", test_loss)\n",
    "print(\"Test Accuracy:\", test_accuracy)\n"
   ]
  },
  {
   "cell_type": "code",
   "execution_count": 33,
   "id": "d4f5c7a8-4124-440d-b565-7bdd1a9cb608",
   "metadata": {},
   "outputs": [
    {
     "name": "stderr",
     "output_type": "stream",
     "text": [
      "WARNING:absl:You are saving your model as an HDF5 file via `model.save()` or `keras.saving.save_model(model)`. This file format is considered legacy. We recommend using instead the native Keras format, e.g. `model.save('my_model.keras')` or `keras.saving.save_model(model, 'my_model.keras')`. \n"
     ]
    }
   ],
   "source": [
    "# Save the model\n",
    "model.save('keras_model.h5')"
   ]
  },
  {
   "cell_type": "code",
   "execution_count": 35,
   "id": "3adbb7ae-3c48-432e-9c99-cb7c6c2443f2",
   "metadata": {},
   "outputs": [
    {
     "name": "stderr",
     "output_type": "stream",
     "text": [
      "WARNING:absl:Compiled the loaded model, but the compiled metrics have yet to be built. `model.compile_metrics` will be empty until you train or evaluate the model.\n",
      "C:\\Users\\DELL\\anaconda3\\Lib\\site-packages\\keras\\src\\models\\functional.py:225: UserWarning: The structure of `inputs` doesn't match the expected structure: input_layer. Received: the structure of inputs=('*',)\n",
      "  warnings.warn(\n"
     ]
    },
    {
     "name": "stdout",
     "output_type": "stream",
     "text": [
      "\u001b[1m1/1\u001b[0m \u001b[32m━━━━━━━━━━━━━━━━━━━━\u001b[0m\u001b[37m\u001b[0m \u001b[1m0s\u001b[0m 118ms/step\n",
      "Predicted class: 0\n"
     ]
    }
   ],
   "source": [
    "import keras.models\n",
    "import numpy as np\n",
    "\n",
    "# Load the trained model\n",
    "model = keras.models.load_model('keras_model.h5')\n",
    "\n",
    "# Convert the new image to a NumPy array\n",
    "new_image = np.array(keras.preprocessing.image.load_img('with_mask_2001.jpg', target_size=(128, 128))) / 255.0\n",
    "\n",
    "# Add a dimension to the new image\n",
    "new_image = np.expand_dims(new_image, axis=0)\n",
    "\n",
    "# Make a prediction on the new image\n",
    "prediction = model.predict([new_image])\n",
    "\n",
    "# Interpret the prediction result\n",
    "predicted_class = np.argmax(prediction)\n",
    "print(f'Predicted class: {predicted_class}')\n",
    "\n"
   ]
  },
  {
   "cell_type": "code",
   "execution_count": null,
   "id": "aa11bec6-63a3-48ea-849e-33ecee015fbc",
   "metadata": {},
   "outputs": [],
   "source": []
  },
  {
   "cell_type": "code",
   "execution_count": null,
   "id": "f8f2e76f-3da8-440f-b401-9ef8b38a0689",
   "metadata": {},
   "outputs": [],
   "source": []
  },
  {
   "cell_type": "code",
   "execution_count": null,
   "id": "962d967c-6f10-4e8a-9167-af2a95b866c3",
   "metadata": {},
   "outputs": [],
   "source": []
  },
  {
   "cell_type": "code",
   "execution_count": null,
   "id": "84eb5df7-5c27-41f9-8ad7-c7875e1ffcea",
   "metadata": {},
   "outputs": [],
   "source": []
  }
 ],
 "metadata": {
  "kernelspec": {
   "display_name": "Python 3 (ipykernel)",
   "language": "python",
   "name": "python3"
  },
  "language_info": {
   "codemirror_mode": {
    "name": "ipython",
    "version": 3
   },
   "file_extension": ".py",
   "mimetype": "text/x-python",
   "name": "python",
   "nbconvert_exporter": "python",
   "pygments_lexer": "ipython3",
   "version": "3.12.4"
  }
 },
 "nbformat": 4,
 "nbformat_minor": 5
}
